<?xml version="1.0" encoding="UTF-8"?>
<!-- Generated by org.testng.reporters.JUnitXMLReporter -->
<testsuite ignored="0" hostname="Testriqs-MacBook-Air-5.local" failures="1" tests="3" name="ActionTest" time="203.665" errors="0" timestamp="11 Jan 2025 12:09:09 GMT">
  <testcase classname="Demo.Invoify.tests.validatingInvoiceActions" name="testInvoiceSaving" time="111.147">
    <skipped/>
  </testcase> <!-- testInvoiceSaving -->
  <testcase classname="Demo.Invoify.tests.validatingInvoiceActions" name="testInvoiceSaving" time="46.308">
    <failure type="java.lang.AssertionError" message="expected [Your invoice has been generated!] but found [Error]">
      <![CDATA[java.lang.AssertionError: expected [Your invoice has been generated!] but found [Error]
at Demo.Invoify.tests.validatingInvoiceActions.testInvoiceSaving(validatingInvoiceActions.java:38)
at java.base/java.util.concurrent.FutureTask.run(FutureTask.java:264)
at java.base/java.util.concurrent.ThreadPoolExecutor.runWorker(ThreadPoolExecutor.java:1136)
at java.base/java.util.concurrent.ThreadPoolExecutor$Worker.run(ThreadPoolExecutor.java:635)
at java.base/java.lang.Thread.run(Thread.java:833)
... Removed 22 stack frames]]>
    </failure>
  </testcase> <!-- testInvoiceSaving -->
  <testcase classname="Demo.Invoify.tests.validatingInvoiceActions" name="testNavigation" time="8.562"/>
</testsuite> <!-- ActionTest -->
