<?xml version="1.0" encoding="UTF-8"?>
<testng-results ignored="0" total="9" passed="5" failed="2" skipped="2">
  <reporter-output>
  </reporter-output>
  <suite started-at="2025-01-11T13:05:09Z" name="Suite" finished-at="2025-01-11T13:08:20Z" duration-ms="190786">
    <groups>
    </groups>
    <test started-at="2025-01-11T13:05:09Z" name="UploadTest" finished-at="2025-01-11T13:07:52Z" duration-ms="162715">
      <class name="Demo.Invoify.tests.verifyAttachmentUpload">
        <test-method is-config="true" signature="launchApplication()[pri:0, instance:Demo.Invoify.tests.verifyAttachmentUpload@242aa8d9]" started-at="2025-01-11T13:05:09Z" name="launchApplication" finished-at="2025-01-11T13:05:44Z" duration-ms="34692" status="PASS">
          <reporter-output>
          </reporter-output>
        </test-method> <!-- launchApplication -->
        <test-method signature="testSignatureUpload()[pri:0, instance:Demo.Invoify.tests.verifyAttachmentUpload@242aa8d9]" started-at="2025-01-11T13:05:44Z" name="testSignatureUpload" finished-at="2025-01-11T13:06:53Z" duration-ms="69821" status="PASS">
          <reporter-output>
          </reporter-output>
        </test-method> <!-- testSignatureUpload -->
        <test-method signature="verifyBillAttachement()[pri:0, instance:Demo.Invoify.tests.verifyAttachmentUpload@242aa8d9]" started-at="2025-01-11T13:06:53Z" name="verifyBillAttachement" finished-at="2025-01-11T13:07:24Z" duration-ms="30519" status="SKIP">
          <exception class="java.lang.AssertionError">
            <message>
              <![CDATA[expected [false] but found [true]]]>
            </message>
            <full-stacktrace>
              <![CDATA[java.lang.AssertionError: expected [false] but found [true]
at org.testng.Assert.fail(Assert.java:96)
at org.testng.Assert.failNotEquals(Assert.java:776)
at org.testng.Assert.assertFalse(Assert.java:65)
at org.testng.Assert.assertFalse(Assert.java:75)
at Demo.Invoify.tests.verifyAttachmentUpload.verifyBillAttachement(verifyAttachmentUpload.java:26)
at java.base/jdk.internal.reflect.NativeMethodAccessorImpl.invoke0(Native Method)
at java.base/jdk.internal.reflect.NativeMethodAccessorImpl.invoke(NativeMethodAccessorImpl.java:77)
at java.base/jdk.internal.reflect.DelegatingMethodAccessorImpl.invoke(DelegatingMethodAccessorImpl.java:43)
at java.base/java.lang.reflect.Method.invoke(Method.java:568)
at org.testng.internal.MethodInvocationHelper.invokeMethod(MethodInvocationHelper.java:124)
at org.testng.internal.Invoker.invokeMethod(Invoker.java:583)
at org.testng.internal.Invoker.invokeTestMethod(Invoker.java:719)
at org.testng.internal.Invoker.invokeTestMethods(Invoker.java:989)
at org.testng.internal.TestMethodWorker.invokeTestMethods(TestMethodWorker.java:125)
at org.testng.internal.TestMethodWorker.run(TestMethodWorker.java:109)
at org.testng.TestRunner.privateRun(TestRunner.java:648)
at org.testng.TestRunner.run(TestRunner.java:505)
at org.testng.SuiteRunner.runTest(SuiteRunner.java:455)
at org.testng.SuiteRunner.access$000(SuiteRunner.java:40)
at org.testng.SuiteRunner$SuiteWorker.run(SuiteRunner.java:489)
at org.testng.internal.thread.ThreadUtil$1.call(ThreadUtil.java:52)
at java.base/java.util.concurrent.FutureTask.run(FutureTask.java:264)
at java.base/java.util.concurrent.ThreadPoolExecutor.runWorker(ThreadPoolExecutor.java:1136)
at java.base/java.util.concurrent.ThreadPoolExecutor$Worker.run(ThreadPoolExecutor.java:635)
at java.base/java.lang.Thread.run(Thread.java:833)
]]>
            </full-stacktrace>
          </exception> <!-- java.lang.AssertionError -->
          <reporter-output>
          </reporter-output>
        </test-method> <!-- verifyBillAttachement -->
        <test-method signature="verifyBillAttachement()[pri:0, instance:Demo.Invoify.tests.verifyAttachmentUpload@242aa8d9]" started-at="2025-01-11T13:07:24Z" name="verifyBillAttachement" finished-at="2025-01-11T13:07:50Z" duration-ms="26535" status="FAIL">
          <exception class="java.lang.AssertionError">
            <message>
              <![CDATA[expected [false] but found [true]]]>
            </message>
            <full-stacktrace>
              <![CDATA[java.lang.AssertionError: expected [false] but found [true]
at org.testng.Assert.fail(Assert.java:96)
at org.testng.Assert.failNotEquals(Assert.java:776)
at org.testng.Assert.assertFalse(Assert.java:65)
at org.testng.Assert.assertFalse(Assert.java:75)
at Demo.Invoify.tests.verifyAttachmentUpload.verifyBillAttachement(verifyAttachmentUpload.java:26)
at java.base/jdk.internal.reflect.NativeMethodAccessorImpl.invoke0(Native Method)
at java.base/jdk.internal.reflect.NativeMethodAccessorImpl.invoke(NativeMethodAccessorImpl.java:77)
at java.base/jdk.internal.reflect.DelegatingMethodAccessorImpl.invoke(DelegatingMethodAccessorImpl.java:43)
at java.base/java.lang.reflect.Method.invoke(Method.java:568)
at org.testng.internal.MethodInvocationHelper.invokeMethod(MethodInvocationHelper.java:124)
at org.testng.internal.Invoker.invokeMethod(Invoker.java:583)
at org.testng.internal.Invoker.retryFailed(Invoker.java:839)
at org.testng.internal.Invoker.invokeTestMethods(Invoker.java:1010)
at org.testng.internal.TestMethodWorker.invokeTestMethods(TestMethodWorker.java:125)
at org.testng.internal.TestMethodWorker.run(TestMethodWorker.java:109)
at org.testng.TestRunner.privateRun(TestRunner.java:648)
at org.testng.TestRunner.run(TestRunner.java:505)
at org.testng.SuiteRunner.runTest(SuiteRunner.java:455)
at org.testng.SuiteRunner.access$000(SuiteRunner.java:40)
at org.testng.SuiteRunner$SuiteWorker.run(SuiteRunner.java:489)
at org.testng.internal.thread.ThreadUtil$1.call(ThreadUtil.java:52)
at java.base/java.util.concurrent.FutureTask.run(FutureTask.java:264)
at java.base/java.util.concurrent.ThreadPoolExecutor.runWorker(ThreadPoolExecutor.java:1136)
at java.base/java.util.concurrent.ThreadPoolExecutor$Worker.run(ThreadPoolExecutor.java:635)
at java.base/java.lang.Thread.run(Thread.java:833)
]]>
            </full-stacktrace>
          </exception> <!-- java.lang.AssertionError -->
          <reporter-output>
          </reporter-output>
        </test-method> <!-- verifyBillAttachement -->
        <test-method is-config="true" signature="quitDriver()[pri:0, instance:Demo.Invoify.tests.verifyAttachmentUpload@242aa8d9]" started-at="2025-01-11T13:07:51Z" name="quitDriver" finished-at="2025-01-11T13:07:52Z" duration-ms="221" status="PASS">
          <reporter-output>
          </reporter-output>
        </test-method> <!-- quitDriver -->
      </class> <!-- Demo.Invoify.tests.verifyAttachmentUpload -->
    </test> <!-- UploadTest -->
    <test started-at="2025-01-11T13:05:09Z" name="DataTest" finished-at="2025-01-11T13:08:19Z" duration-ms="190023">
      <class name="Demo.Invoify.tests.dataInputValidation">
        <test-method is-config="true" signature="launchApplication()[pri:0, instance:Demo.Invoify.tests.dataInputValidation@6d304f9d]" started-at="2025-01-11T13:05:09Z" name="launchApplication" finished-at="2025-01-11T13:05:43Z" duration-ms="34604" status="PASS">
          <reporter-output>
          </reporter-output>
        </test-method> <!-- launchApplication -->
        <test-method signature="testBankDetailsAreEntered()[pri:0, instance:Demo.Invoify.tests.dataInputValidation@6d304f9d]" started-at="2025-01-11T13:05:44Z" name="testBankDetailsAreEntered" finished-at="2025-01-11T13:07:01Z" duration-ms="77162" status="PASS">
          <reporter-output>
          </reporter-output>
        </test-method> <!-- testBankDetailsAreEntered -->
        <test-method signature="testProperTotalCalculation()[pri:0, instance:Demo.Invoify.tests.dataInputValidation@6d304f9d]" started-at="2025-01-11T13:07:01Z" name="testProperTotalCalculation" finished-at="2025-01-11T13:07:31Z" duration-ms="29914" status="PASS">
          <reporter-output>
          </reporter-output>
        </test-method> <!-- testProperTotalCalculation -->
        <test-method signature="testToggleButtonEnabling()[pri:0, instance:Demo.Invoify.tests.dataInputValidation@6d304f9d]" started-at="2025-01-11T13:07:31Z" name="testToggleButtonEnabling" finished-at="2025-01-11T13:08:19Z" duration-ms="48021" status="PASS">
          <reporter-output>
          </reporter-output>
        </test-method> <!-- testToggleButtonEnabling -->
        <test-method is-config="true" signature="quitDriver()[pri:0, instance:Demo.Invoify.tests.dataInputValidation@6d304f9d]" started-at="2025-01-11T13:08:19Z" name="quitDriver" finished-at="2025-01-11T13:08:19Z" duration-ms="165" status="PASS">
          <reporter-output>
          </reporter-output>
        </test-method> <!-- quitDriver -->
      </class> <!-- Demo.Invoify.tests.dataInputValidation -->
    </test> <!-- DataTest -->
    <test started-at="2025-01-11T13:05:09Z" name="ActionTest" finished-at="2025-01-11T13:08:20Z" duration-ms="190786">
      <class name="Demo.Invoify.tests.validatingInvoiceActions">
        <test-method is-config="true" signature="launchApplication()[pri:0, instance:Demo.Invoify.tests.validatingInvoiceActions@2c88b9fc]" started-at="2025-01-11T13:05:09Z" name="launchApplication" finished-at="2025-01-11T13:05:43Z" duration-ms="34623" status="PASS">
          <reporter-output>
          </reporter-output>
        </test-method> <!-- launchApplication -->
        <test-method signature="testInvoiceSaving()[pri:0, instance:Demo.Invoify.tests.validatingInvoiceActions@2c88b9fc]" started-at="2025-01-11T13:05:44Z" name="testInvoiceSaving" finished-at="2025-01-11T13:07:46Z" duration-ms="122271" status="SKIP">
          <exception class="java.lang.AssertionError">
            <message>
              <![CDATA[expected [Your invoice has been generated!] but found [Error]]]>
            </message>
            <full-stacktrace>
              <![CDATA[java.lang.AssertionError: expected [Your invoice has been generated!] but found [Error]
at org.testng.Assert.fail(Assert.java:96)
at org.testng.Assert.failNotEquals(Assert.java:776)
at org.testng.Assert.assertEqualsImpl(Assert.java:137)
at org.testng.Assert.assertEquals(Assert.java:118)
at org.testng.Assert.assertEquals(Assert.java:453)
at org.testng.Assert.assertEquals(Assert.java:463)
at Demo.Invoify.tests.validatingInvoiceActions.testInvoiceSaving(validatingInvoiceActions.java:38)
at java.base/jdk.internal.reflect.NativeMethodAccessorImpl.invoke0(Native Method)
at java.base/jdk.internal.reflect.NativeMethodAccessorImpl.invoke(NativeMethodAccessorImpl.java:77)
at java.base/jdk.internal.reflect.DelegatingMethodAccessorImpl.invoke(DelegatingMethodAccessorImpl.java:43)
at java.base/java.lang.reflect.Method.invoke(Method.java:568)
at org.testng.internal.MethodInvocationHelper.invokeMethod(MethodInvocationHelper.java:124)
at org.testng.internal.Invoker.invokeMethod(Invoker.java:583)
at org.testng.internal.Invoker.invokeTestMethod(Invoker.java:719)
at org.testng.internal.Invoker.invokeTestMethods(Invoker.java:989)
at org.testng.internal.TestMethodWorker.invokeTestMethods(TestMethodWorker.java:125)
at org.testng.internal.TestMethodWorker.run(TestMethodWorker.java:109)
at org.testng.TestRunner.privateRun(TestRunner.java:648)
at org.testng.TestRunner.run(TestRunner.java:505)
at org.testng.SuiteRunner.runTest(SuiteRunner.java:455)
at org.testng.SuiteRunner.access$000(SuiteRunner.java:40)
at org.testng.SuiteRunner$SuiteWorker.run(SuiteRunner.java:489)
at org.testng.internal.thread.ThreadUtil$1.call(ThreadUtil.java:52)
at java.base/java.util.concurrent.FutureTask.run(FutureTask.java:264)
at java.base/java.util.concurrent.ThreadPoolExecutor.runWorker(ThreadPoolExecutor.java:1136)
at java.base/java.util.concurrent.ThreadPoolExecutor$Worker.run(ThreadPoolExecutor.java:635)
at java.base/java.lang.Thread.run(Thread.java:833)
]]>
            </full-stacktrace>
          </exception> <!-- java.lang.AssertionError -->
          <reporter-output>
          </reporter-output>
        </test-method> <!-- testInvoiceSaving -->
        <test-method signature="testInvoiceSaving()[pri:0, instance:Demo.Invoify.tests.validatingInvoiceActions@2c88b9fc]" started-at="2025-01-11T13:07:46Z" name="testInvoiceSaving" finished-at="2025-01-11T13:08:13Z" duration-ms="26908" status="FAIL">
          <exception class="java.lang.AssertionError">
            <message>
              <![CDATA[expected [Your invoice has been generated!] but found [Error]]]>
            </message>
            <full-stacktrace>
              <![CDATA[java.lang.AssertionError: expected [Your invoice has been generated!] but found [Error]
at org.testng.Assert.fail(Assert.java:96)
at org.testng.Assert.failNotEquals(Assert.java:776)
at org.testng.Assert.assertEqualsImpl(Assert.java:137)
at org.testng.Assert.assertEquals(Assert.java:118)
at org.testng.Assert.assertEquals(Assert.java:453)
at org.testng.Assert.assertEquals(Assert.java:463)
at Demo.Invoify.tests.validatingInvoiceActions.testInvoiceSaving(validatingInvoiceActions.java:38)
at java.base/jdk.internal.reflect.NativeMethodAccessorImpl.invoke0(Native Method)
at java.base/jdk.internal.reflect.NativeMethodAccessorImpl.invoke(NativeMethodAccessorImpl.java:77)
at java.base/jdk.internal.reflect.DelegatingMethodAccessorImpl.invoke(DelegatingMethodAccessorImpl.java:43)
at java.base/java.lang.reflect.Method.invoke(Method.java:568)
at org.testng.internal.MethodInvocationHelper.invokeMethod(MethodInvocationHelper.java:124)
at org.testng.internal.Invoker.invokeMethod(Invoker.java:583)
at org.testng.internal.Invoker.retryFailed(Invoker.java:839)
at org.testng.internal.Invoker.invokeTestMethods(Invoker.java:1010)
at org.testng.internal.TestMethodWorker.invokeTestMethods(TestMethodWorker.java:125)
at org.testng.internal.TestMethodWorker.run(TestMethodWorker.java:109)
at org.testng.TestRunner.privateRun(TestRunner.java:648)
at org.testng.TestRunner.run(TestRunner.java:505)
at org.testng.SuiteRunner.runTest(SuiteRunner.java:455)
at org.testng.SuiteRunner.access$000(SuiteRunner.java:40)
at org.testng.SuiteRunner$SuiteWorker.run(SuiteRunner.java:489)
at org.testng.internal.thread.ThreadUtil$1.call(ThreadUtil.java:52)
at java.base/java.util.concurrent.FutureTask.run(FutureTask.java:264)
at java.base/java.util.concurrent.ThreadPoolExecutor.runWorker(ThreadPoolExecutor.java:1136)
at java.base/java.util.concurrent.ThreadPoolExecutor$Worker.run(ThreadPoolExecutor.java:635)
at java.base/java.lang.Thread.run(Thread.java:833)
]]>
            </full-stacktrace>
          </exception> <!-- java.lang.AssertionError -->
          <reporter-output>
          </reporter-output>
        </test-method> <!-- testInvoiceSaving -->
        <test-method signature="testNavigation()[pri:0, instance:Demo.Invoify.tests.validatingInvoiceActions@2c88b9fc]" started-at="2025-01-11T13:08:13Z" name="testNavigation" finished-at="2025-01-11T13:08:19Z" duration-ms="6076" status="PASS">
          <reporter-output>
          </reporter-output>
        </test-method> <!-- testNavigation -->
        <test-method is-config="true" signature="quitDriver()[pri:0, instance:Demo.Invoify.tests.validatingInvoiceActions@2c88b9fc]" started-at="2025-01-11T13:08:19Z" name="quitDriver" finished-at="2025-01-11T13:08:20Z" duration-ms="110" status="PASS">
          <reporter-output>
          </reporter-output>
        </test-method> <!-- quitDriver -->
      </class> <!-- Demo.Invoify.tests.validatingInvoiceActions -->
    </test> <!-- ActionTest -->
  </suite> <!-- Suite -->
</testng-results>
